<?xml version="1.0"?>
<robot xmlns:xacro="http://www.ros.org/wiki/xacro">

    <!-- Palm axis:1 -->
    <link name="palm_axis:1">
    <inertial>
        <origin xyz="0 0.008585 0.0125" rpy="0 0 0"/>
        <mass value="0.0509809"/>
        <inertia ixx="9.79681e-06" ixy="0.0" ixz="0.0" iyy="1.37535e-05" iyz="0.0" izz="1.88432e-05"/>
    </inertial>
    <visual>
        <origin xyz="0 0 0.0125" rpy="0 0 0"/>
        <geometry>
        <mesh filename="package://rh8d_mujoco_description/meshes/palm_axis.stl" scale="0.001 0.001 0.001"/>
        </geometry>
        <material name="palm_axis:1_color">
        <color rgba="0.74902 0.74902 0.74902 1.0"/>
        </material>
    </visual>
    <collision>
        <origin xyz="0 0 0.0125" rpy="0 0 0"/>
        <geometry>
        <mesh filename="package://rh8d_mujoco_description/meshes/palm_axis.stl" scale="0.001 0.001 0.001"/>
        </geometry>
    </collision>
    </link>

    <!-- Joint: forearm:1 -> palm_axis:1 -->
    <joint name="palm_axis:1--forearm:1" type="revolute">
        <origin xyz="0 -0.165 -0.01275" rpy="0 0 0"/>
        <axis xyz="0.0 0.0 -1.0"/>
        <parent link="forearm:1"/>
        <child link="palm_axis:1"/>
        <dynamics damping="0.05" friction="0.005"/>
        <limit effort="2.5" lower="-1.57079632679" upper="1.57079632679" velocity="5.0"/>
    </joint>

    <!-- Palm L:1 -->
    <link name="palmL:1">
    <inertial>
        <origin xyz="-0.0063987 -0.040539 0.0106004" rpy="0 0 0"/>
        <mass value="0.0826631"/>
        <inertia ixx="5.182e-05" ixy="-1.66912e-05" ixz="-1.48116e-05" iyy="7.49342e-05" iyz="-1.29095e-05" izz="9.32881e-05"/>
    </inertial>
    <visual>
        <origin xyz="-0.0265 0 0" rpy="0 0 0"/>
        <geometry>
        <mesh filename="package://rh8d_mujoco_description/meshes/palmL.stl" scale="0.001 0.001 0.001"/>
        </geometry>
        <material name="palmL:1_color">
        <color rgba="0.74902 0.74902 0.74902 1.0"/>
        </material>
    </visual>
    <collision>
        <origin xyz="-0.0265 0 0" rpy="0 0 0"/>
        <geometry>
        <mesh filename="package://rh8d_mujoco_description/meshes/palmL.stl" scale="0.001 0.001 0.001"/>
        </geometry>
    </collision>
    </link>

    <!-- Joint: palm_axis:1 -> palmL:1 -->
    <joint name="palmL:1--palm_axis:1" type="revolute">
        <origin xyz="-0.0265 0 0.0125" rpy="3.14159265359 0 3.14159265359"/>
        <axis xyz="-1.0 0.0 0.0"/>
        <parent link="palm_axis:1"/>
        <child link="palmL:1"/>
        <dynamics damping="0.05" friction="0.005"/>
        <limit effort="2.5" lower="-0.785398163395" upper="0.785398163395" velocity="5.0"/>
    </joint>

</robot>