<?xml version="1.0"?>
<robot xmlns:xacro="http://www.ros.org/wiki/xacro">

    <!-- Small Proximal -->
    <link name="Small_Proximal">
    <inertial>
        <origin xyz="-0.00506269343293 -0.000180281356188 -0.0109173041713" rpy="0 0 0"/>
        <mass value="0.00525864"/>
        <inertia ixx="5.33998e-07" ixy="2.78487e-10" ixz="-8.95438e-13" iyy="5.63087e-07" iyz="3.11448e-08" izz="1.84796e-07"/>
    </inertial>
    <visual>
        <origin xyz="-0.00506242096312 0 -0.0129379154082" rpy="0 0 0"/>
        <geometry>
        <mesh filename="package://rh8d_mujoco_description/meshes/phalanx.stl" scale="0.001 0.001 0.001"/>
        </geometry>
        <material name="Small_Proximal_color">
        <color rgba="0.74902 0.74902 0.74902 1.0"/>
        </material>
    </visual>
    <collision>
        <origin xyz="-0.00506242096312 0 -0.0129379154082" rpy="0 0 0"/>
        <geometry>
        <mesh filename="package://rh8d_mujoco_description/meshes/phalanx.stl" scale="0.001 0.001 0.001"/>
        </geometry>
    </collision>
    </link>

    <!-- Joint: palmL:1 -> Small_Proximal -->
    <joint name="Small_Proximal--palmL:1" type="revolute">
        <origin xyz="-0.0591609 -0.07417 0.00246184" rpy="-1.77486172903 0.138702392285 -0.20406540224"/>
        <axis xyz="-1.0 0.0 0.0"/>
        <parent link="palmL:1"/>
        <child link="Small_Proximal"/>
            
        <mimic joint="Ring_Proximal--palmL:1"
                    multiplier="1.0"
                    offset="0.0"/>

        <dynamics damping="0.002" friction="0.0"/>
        <limit effort="0.5" lower="0" upper="1.57079632679" velocity="10.0"/>
    </joint>

    <!-- Small Middle -->
    <link name="Small_Middle">
    <inertial>
        <origin xyz="-0.00506269066777 -0.000180261959261 -0.0109173001571" rpy="0 0 0"/>
        <mass value="0.00525864"/>
        <inertia ixx="5.33998e-07" ixy="2.78487e-10" ixz="-8.95438e-13" iyy="5.63087e-07" iyz="3.11448e-08" izz="1.84796e-07"/>
    </inertial>
    <visual>
        <origin xyz="-0.00506232259591 0 -0.0129378963001" rpy="0 0 0"/>
        <geometry>
        <mesh filename="package://rh8d_mujoco_description/meshes/phalanx.stl" scale="0.001 0.001 0.001"/>
        </geometry>
        <material name="Small_Middle_color">
        <color rgba="0.74902 0.74902 0.74902 1.0"/>
        </material>
    </visual>
    <collision>
        <origin xyz="-0.00506232259591 0 -0.0129378963001" rpy="0 0 0"/>
        <geometry>
        <mesh filename="package://rh8d_mujoco_description/meshes/phalanx.stl" scale="0.001 0.001 0.001"/>
        </geometry>
    </collision>
    </link>

    <!-- Joint: Small_Proximal -> Small_Middle -->
    <joint name="Small_Middle--Small_Proximal" type="revolute">
        <origin xyz="6.25112164948e-05 0 -0.0258751651529" rpy="0 0 0"/>
        <axis xyz="-1.0 0.0 0.0"/>
        <parent link="Small_Proximal"/>
        <child link="Small_Middle"/>
            
        <mimic joint="Small_Proximal--palmL:1"
                    multiplier="0.9"
                    offset="0.0"/>

        <dynamics damping="0.002" friction="0.0"/>
        <limit effort="0.5" lower="0" upper="1.57079632679" velocity="10.0"/>
    </joint>

    <!-- Small Distal -->
    <link name="Small_Distal">
    <inertial>
        <origin xyz="-0.00505708357765 -0.00237055107718 -0.0113148042992" rpy="0 0 0"/>
        <mass value="0.00486055"/>
        <inertia ixx="4.61031e-07" ixy="7.56173e-11" ixz="5.71507e-11" iyy="4.72548e-07" iyz="-5.64479e-08" izz="3.05155e-07"/>
    </inertial>
    <visual>
        <origin xyz="-0.00506253237144 0 0" rpy="0 0 0"/>
        <geometry>
        <mesh filename="package://rh8d_mujoco_description/meshes/tip.stl" scale="0.001 0.001 0.001"/>
        </geometry>
        <material name="Small_Distal_color">
        <color rgba="0.74902 0.74902 0.74902 1.0"/>
        </material>
    </visual>
    <collision>
        <origin xyz="-0.00506253237144 0 0" rpy="0 0 0"/>
        <geometry>
        <mesh filename="package://rh8d_mujoco_description/meshes/tip.stl" scale="0.001 0.001 0.001"/>
        </geometry>
    </collision>
    </link>

    <!-- Joint: Small_Middle -> Small_Distal -->
    <joint name="Small_Distal--Small_Middle" type="revolute">
    <origin xyz="6.26026708029e-05 0 -0.0258751560801" rpy="0 0 0"/>
    <axis xyz="-1.0 0.0 0.0"/>
    <parent link="Small_Middle"/>
    <child link="Small_Distal"/>
        
    <mimic joint="Small_Middle--Small_Proximal"
                multiplier="0.9"
                offset="0.0"/>

    <dynamics damping="0.002" friction="0.0"/>
    <limit effort="0.5" lower="0" upper="1.57079632679" velocity="10.0"/>
    </joint>

</robot>

